Workbook

Sheet 说明 How to
A1: Batch B 人工核对表 · Harper audit sheet (measure 1)
A3: 抽样：Batch B（v2.3，2026-10-25）保留下来的 80 条事实里抽了 50 条（每题约 5 条，定价和重查过的全部纳入；随机种子 20261026，可复现）。
A5: 每一行做四项检查，在 J–M 列选 Y 或 N：
A6: J 链接能打开 Link opens：点 F/G 列的链接，页面能打开（不是 404、不是要登录）。
A7: K 原文在页面上 Text on page：在页面里能找到支持这个值的文字（Cmd+F 搜关键词）。
A8: L 来源可信且标注正确 Source credible & labelled：官网就该是该公司自己的域名；第三方/新闻/搜索收录要是可信来源，且 H 列标注没标错（比如不是第三方却标成官网）。
A9: M 数值一致 Value matches：E 列的值和页面上写的一致（价格、人数、日期等）。
A10: N 列自动计算：四项都是 Y 才算正确。拿不准写在 O 列备注。
A12: 定价那几行内容较多：抽查主要价格（套餐和单价）+ 任意一个子项即可，有一项错就算 N，并在备注写哪项错。
A14: 开始和结束时间请填在「汇总 Summary」页（用于指标 4：核对用时）。
A15: 门槛：≥90% 正确为达成；<80% 为证伪（F1）。

Sheet 核对 Audit
A1: # | B1: 题号 Q | C1: 问题 Question | D1: 公司 Company | E1: 字段 Field + 系统给出的值 Value | F1: 来源 1 Source 1 | G1: 来源 2 Source 2 | H1: 来源标注 Label shown | I1: 状态 Status | J1: J 链接能打开 (Y/N) | K1: K 原文在页面 (Y/N) | L1: L 来源可信且标注正确 (Y/N) | M1: M 数值一致 (Y/N) | N1: N 正确? Correct | O1: O 备注 Notes
A2: 1 | B2: Q01 | C2: 我们是做在线协作文档的，帮我找竞品 | D2: 石墨文档 | E2: [overview] 武汉初心科技旗下在线协同文档品牌，提供文档、表格、幻灯片等云端Office套件，面向个人与企业团队 | F2: https://shimo.im/about | G2: https://shimo.im | H2: 官网 official / 官网 official | I2: 通过 verified | J2: Y | K2: Y | L2: Y | M2: Y | N2: =IF(COUNTA(J2:M2)<4,"",IF(COUNTIF(J2:M2,"Y")=4,"正确","错误")) -> 正确 | O2: [人工核对] about 页写明武汉初心科技；首页写文档、表格、幻灯片等组成的「云端 Office」
A3: 2 | B3: Q01 | C3: 我们是做在线协作文档的，帮我找竞品 | D3: 腾讯文档 | E3: [overview] 腾讯旗下多人协作在线文档平台，支持Word、Excel、PPT、PDF、收集表、思维导图等在线编辑与云端保存，面向个人和企业团队 | F3: https://docs.qq.com | G3: https://www.cnpp.cn/pinpai/135822.html | H3: 官网 official / 搜索收录 search | I3: 通过 verified | J3: Y | K3: Y | L3: Y | M3: Y | N3: =IF(COUNTA(J3:M3)<4,"",IF(COUNTIF(J3:M3,"Y")=4,"正确","错误")) -> 正确 | O3: [人工核对] 官网与十大品牌网均有 Word/Excel/PPT/PDF/收集表/思维导图
A4: 3 | B4: Q01 | C4: 我们是做在线协作文档的，帮我找竞品 | D4: 石墨文档 | E4: [size] 100–499 人（开发屋，2023 年） | F4: https://www.kaifain.com/b/ae4b294ae802d3b1 | H4: 搜索收录 search | I4: 通过 verified | N4: =IF(COUNTA(J4:M4)<4,"",IF(COUNTIF(J4:M4,"Y")=4,"正确","错误")) | O4: [人工核对] 开发屋弹出 Cloudflare 真人验证，未能打开，需人工点验证后补核
A5: 4 | B5: Q01 | C5: 我们是做在线协作文档的，帮我找竞品 | D5: 石墨文档 | E5: [region] 中国 · 武汉，在北京、上海、武汉、深圳设有分支机构和服务中心 | F5: https://shimo.im/about | H5: 官网 official | I5: 通过 verified | J5: Y | K5: Y | L5: Y | M5: N | N5: =IF(COUNTA(J5:M5)<4,"",IF(COUNTIF(J5:M5,"Y")=4,"正确","错误")) -> 错误 | O5: [人工核对] 官网只写北京、上海、武汉设分支机构，没有「深圳」
A6: 5 | B6: Q01 | C6: 我们是做在线协作文档的，帮我找竞品 | D6: 石墨文档 | E6: [funding] 2017 年获今日头条近亿元 B 轮投资；开发屋标注融资阶段为 B++ 轮（2023 年） | F6: https://shimo.im/about | G6: https://www.kaifain.com/b/ae4b294ae802d3b1 | H6: 官网 official / 搜索收录 search | I6: 通过 verified | N6: =IF(COUNTA(J6:M6)<4,"",IF(COUNTIF(J6:M6,"Y")=4,"正确","错误")) | O6: [人工核对] 官网可见 2017 年今日头条近亿元 B 轮（对）；「B++ 轮」来源开发屋被 Cloudflare 验证拦住，未核
A7: 6 | B7: Q02 | C7: 查一下 Notion、Coda、ClickUp 的基本信息 | D7: Notion | E7: [pricing] Free $0 / Plus $10 / Business $20（均每成员每月）/ Enterprise 定制价格 计价单位: 按成员（席位）每月计费 计费方式: 可选按月或按年付款，年付最多省 20%，价格以美元计 附加成本: Custom Agents 免费试用，之后每 1,000 个月度 Notion credits 收费 $10 免费策略: Free 计划 $0，个人页面与块不限量，2 人以上团队受限，单文件上传上限 5MB，页面历史 7 天 当前优惠: 年付相比月付最多可节省 20% | F7: https://www.notion.com/pricing | H7: 官网 official | I7: 通过 verified | J7: Y | K7: Y | L7: Y | M7: Y | N7: =IF(COUNTA(J7:M7)<4,"",IF(COUNTIF(J7:M7,"Y")=4,"正确","错误")) -> 正确 | O7: [人工核对] $0/$10/$20/定制 与年付最多省 20% 均一致
A8: 7 | B8: Q02 | C8: 查一下 Notion、Coda、ClickUp 的基本信息 | D8: Coda | E8: [pricing] 自由 $0/文档制作者/月；专业版 $12/月（年付 $10）；团队 $36/月（年付 $30）；企业 定制 计价单位: 按每个 Doc Maker（文档制作者）每月计费，查看者不限 计费方式: 分月付与年付，年付更便宜：专业版 $10、团队 $30（美元） 免费策略: 自由计划 $0：无限编辑者与查看者，文档行数/对象有限，自动化每月35次、7天历史 | F8: https://www.partnershare.cn/product/coda-coda/price | H8: 官网 official | I8: 重查后通过 re-queried | J8: Y | K8: Y | L8: N | M8: Y | N8: =IF(COUNTA(J8:M8)<4,"",IF(COUNTIF(J8:M8,"Y")=4,"正确","错误")) -> 错误 | O8: [人工核对] 数值与 PartnerShare 页一致，但 PartnerShare 是第三方软件目录，却标成官网 official
A9: 8 | B9: Q02 | C9: 查一下 Notion、Coda、ClickUp 的基本信息 | D9: ClickUp | E9: [pricing] Free Forever 免费 / Unlimited $7 每用户每月（年付）/ Business $12 每用户每月（年付）/ Enterprise 联系销售定制 计价单位: 按每用户每月计价，未注明最低席位数 计费方式: 价格分月付与年付，年付最高省33%；Unlimited 年付$7、月付$10，Business 年付$12、月付$19 附加成本: Business 含每月5K自动化（价值$100），Enterprise 含250K自动化（价值$750）；另有独立AI定价 免费策略: Free Forever 免费计划：任务和用户不限量，含白板但有限额，无需信用卡 当前优惠: 年付最高可省33%，AI 年付最高省20% | F9: https://clickup.com/pricing | G9: https://clickup.com/features/tasks | H9: 官网 official / 官网 official | I9: 重查后通过 re-queried | J9: Y | K9: Y | L9: Y | M9: Y | N9: =IF(COUNTA(J9:M9)<4,"",IF(COUNTIF(J9:M9,"Y")=4,"正确","错误")) -> 正确 | O9: [人工核对] Unlimited $7、Business $12（年付）、年付最高省 33%、Business 5K 自动化均一致
A10: 9 | B10: Q02 | C10: 查一下 Notion、Coda、ClickUp 的基本信息 | D10: ClickUp | E10: [features] 任务管理、文档与Wiki、白板流程图、内置时间追踪与工时审批、AI Brain与Super Agents | F10: https://clickup.com/features/tasks | G10: https://clickup.com/features/docs | H10: 官网 official / 官网 official | I10: 通过 verified | J10: Y | K10: Y | L10: Y | M10: Y | N10: =IF(COUNTA(J10:M10)<4,"",IF(COUNTIF(J10:M10,"Y")=4,"正确","错误")) -> 正确 | O10: [人工核对] 任务、文档/Wiki、白板、时间追踪、Brain、Super Agents 都有；「工时审批」页面未明确写
A11: 10 | B11: Q02 | C11: 查一下 Notion、Coda、ClickUp 的基本信息 | D11: ClickUp | E11: [overview] 一体化工作协作平台，整合任务、文档、目标、聊天与AI，面向全球团队替代多个分散工具 | F11: https://clickup.com | G11: https://clickup.com/about | H11: 官网 official / 官网 official | I11: 通过 verified | J11: Y | K11: Y | L11: Y | M11: Y | N11: =IF(COUNTA(J11:M11)<4,"",IF(COUNTIF(J11:M11,"Y")=4,"正确","错误")) -> 正确 | O11: [人工核对] about 页写用一个平台取代分散工具、融合 AI；「目标」未在该页明确出现
A12: 11 | B12: Q03 | C12: Compare Asana, Monday.com and Trello pricing | D12: Monday.com | E12: [pricing] Free $0 / Basic $9 / Standard $12 / Pro $19 per seat per month / Enterprise custom price Pricing unit: Per seat per month; pricing page example uses 10 seats (e.g. $9 x 10 seats = $90) Billing: Prices shown billed annually (Yearly SAVE 18%); monthly billing option available Extra costs: AI credits beyond plan allowance: 1,000 credits = $10, 2,000 = $20, 3,000 = $30; extra API calls purchasable Free tier & trial: Free forever plan: up to 2 seats, up to 3 boards, up to 3 Docs, 200+ templates, 8 column types; no credit card needed Current offer: Special offer: $10 off/month on Basic, $20 off/month on Standard, $30 off/month on Pro | F12: https://monday.com/pricing | H12: 官网 official | I12: 通过 verified | J12: Y | K12: Y | L12: Y | M12: Y | N12: =IF(COUNTA(J12:M12)<4,"",IF(COUNTIF(J12:M12,"Y")=4,"正确","错误")) -> 正确 | O12: [人工核对] $0/$9/$12/$19、年付省 18%、特惠 $10/$20/$30 均一致
A13: 12 | B13: Q03 | C13: Compare Asana, Monday.com and Trello pricing | D13: Trello | E13: [pricing] Free $0 / Standard $5 per user/month billed annually ($6 billed monthly) / Premium $10 per user/month billed annually ($12.50 billed monthly) / Enterprise (contact sales) Free tier & trial: Free plan for individuals or small teams, up to 10 collaborators per Workspace | F13: https://www.trello.com/pricing | G13: https://lifestack.ai/blog/trello-pricing | H13: 搜索收录 search / 搜索收录 search | I13: 通过 verified | J13: Y | K13: Y | L13: N | M13: N | N13: =IF(COUNTA(J13:M13)<4,"",IF(COUNTIF(J13:M13,"Y")=4,"正确","错误")) -> 错误 | O13: [人工核对] trello.com 是官网却标成搜索收录；页面 Enterprise 标价 $17.50/人/月（年付），不是「联系销售」
A14: 13 | B14: Q04 | C14: 我们做 CRM，帮我查 Salesforce、HubSpot、纷享销客 | D14: Salesforce | E14: [pricing] Starter Suite $25 USD/user/month；其余产品（Agentforce、Sales Cloud、Service Cloud 等）价格需查看各产品页或联系销售 计价单位: 按用户每月计费（USD/user/month） 免费策略: 可免费开始使用（Start for free），具体免费额度未说明 | F14: https://www.salesforce.com/ap/?ir=1&bc=DB | G14: https://www.salesforce.com/pricing/?bc=DB | H14: 官网 official / 官网 official | I14: 通过 verified | J14: Y | K14: Y | L14: Y | M14: Y | N14: =IF(COUNTA(J14:M14)<4,"",IF(COUNTIF(J14:M14,"Y")=4,"正确","错误")) -> 正确 | O14: [人工核对] $25/用户/月 与「免费开始」在 /ap 页可见；/pricing 页未直接显示 $25
A15: 14 | B15: Q04 | C15: 我们做 CRM，帮我查 Salesforce、HubSpot、纷享销客 | D15: HubSpot | E15: [pricing] Sales Hub：免费 $0 / Starter $50.00 每月2用户 / Professional $500.00 5用户 / Enterprise $1,200.00 每月10用户 计价单位: 按用户数计价：Starter 含2用户、Professional 含5用户、Enterprise 含10用户 计费方式: 默认按年计费，月付价格通常高10–20% 附加成本: 额外营销联系人按每千个$50–$100计费，另有入职、专属支持等附加费 免费策略: 免费CRM含联系人、交易、邮件跟踪等基础功能，所有套餐用户均可使用免费功能 当前优惠: Vendr数据显示买家平均节省18%，常见低于标价15–30% | F15: https://www.partnershare.cn/product/hubspot-sales-hub/price | G15: https://www.vendr.com/marketplace/hubspot | H15: 官网 official / 官网 official | I15: 重查后通过 re-queried | J15: Y | K15: Y | L15: N | M15: Y | N15: =IF(COUNTA(J15:M15)<4,"",IF(COUNTIF(J15:M15,"Y")=4,"正确","错误")) -> 错误 | O15: [人工核对] 数值与 PartnerShare 一致，但 PartnerShare、Vendr 都是第三方，被标成官网；且是旧版定价，未与 HubSpot 官网对照
A16: 15 | B16: Q04 | C16: 我们做 CRM，帮我查 Salesforce、HubSpot、纷享销客 | D16: 纷享销客 | E16: [pricing] 专业版 ¥119/人/月、旗舰版 ¥220/人/月、AI旗舰版 ¥273/人/月，均12个月起购 计价单位: 按账号数计费，每用户每月，12个月起购 计费方式: 按人/月标价，12个月起购，人民币计价 附加成本: 支持CRM系统定制报价，具体报价需咨询热线 免费策略: 官网提供免费试用入口，未说明试用时长与功能限制 | F16: https://www.fxiaoke.com/ap/market-price | G16: https://www.fxiaoke.com/ | H16: 官网 official / 官网 official | I16: 重查后通过 re-queried | J16: Y | K16: Y | L16: Y | M16: Y | N16: =IF(COUNTA(J16:M16)<4,"",IF(COUNTIF(J16:M16,"Y")=4,"正确","错误")) -> 正确 | O16: [人工核对] ¥119/¥220/¥273、12 个月起购均一致
A17: 16 | B17: Q04 | C17: 我们做 CRM，帮我查 Salesforce、HubSpot、纷享销客 | D17: 纷享销客 | E17: [features] AI销售助理、线索与商机管理、CPQ报价下单、客户360°洞察、智能客服与工单、PaaS定制与BI分析 | F17: https://www.fxiaoke.com/ | G17: https://www.fxiaoke.com/ap/product-xs/ | H17: 官网 official / 官网 official | I17: 通过 verified | J17: Y | K17: Y | L17: Y | M17: Y | N17: =IF(COUNTA(J17:M17)<4,"",IF(COUNTIF(J17:M17,"Y")=4,"正确","错误")) -> 正确 | O17: [人工核对] 销售 AI、线索/商机、CPQ、智能客服、PaaS、BI 均在官网导航中
A18: 17 | B18: Q04 | C18: 我们做 CRM，帮我查 Salesforce、HubSpot、纷享销客 | D18: HubSpot | E18: [region] 美国 · 波士顿，2006 年创立，服务全球数百万企业 | F18: https://www.hubspot.com/our-story | H18: 官网 official | I18: 通过 verified | J18: Y | K18: Y | L18: Y | M18: N | N18: =IF(COUNTA(J18:M18)<4,"",IF(COUNTIF(J18:M18,"Y")=4,"正确","错误")) -> 错误 | O18: [人工核对] 2006、波士顿正确；页面写 306,000 名客户，不是「数百万企业」
A19: 18 | B19: Q05 | C19: Find competitors of Calendly | D19: Doodle | E19: [size] 100+ employees spread over four countries (Doodle careers site, 2026); LinkedIn lists 51–200 employees | F19: https://careers.doodle.com/ | G19: https://www.linkedin.com/company/doodle-ag | H19: 官网 official / 搜索收录 search | I19: 重查后通过 re-queried | J19: N | K19: N | L19: Y | M19: Y | N19: =IF(COUNTA(J19:M19)<4,"",IF(COUNTIF(J19:M19,"Y")=4,"正确","错误")) -> 错误 | O19: [人工核对] 官网 100+、四国一致；LinkedIn 需登录，51–200 无法核实
A20: 19 | B20: Q05 | C20: Find competitors of Calendly | D20: Doodle | E20: [funding] 2022 年 9 月 A 轮 5400 万美元，Seven Seven Six 领投，Acrew Capital、FTX Ventures、50T Funds 参投，估值 7.04 亿美元 | F20: https://www.coindesk.com/business/2022/09/13/nft-marketplace-doodles-raises-54m-at-704m-valuation | G20: https://multiples.vc/private-comps/doodles | H20: 网页 web / 网页 web | I20: 重查后通过 re-queried | J20: Y | K20: Y | L20: N | M20: N | N20: =IF(COUNTA(J20:M20)<4,"",IF(COUNTIF(J20:M20,"Y")=4,"正确","错误")) -> 错误 | O20: [人工核对] 两个来源讲的是 NFT 项目 Doodles，不是排期工具 Doodle，公司张冠李戴
A21: 20 | B21: Q05 | C21: Find competitors of Calendly | D21: HubSpot Meetings | E21: [funding] 已上市（IPO Status: Public）；累计融资 $100.5M，共 6 轮，最近为 2012 年 11 月 $35M Series E | F21: https://startupintros.com/orgs/hubspot | H21: 网页 web | I21: 重查后通过 re-queried | J21: Y | K21: Y | L21: Y | M21: Y | N21: =IF(COUNTA(J21:M21)<4,"",IF(COUNTIF(J21:M21,"Y")=4,"正确","错误")) -> 正确 | O21: [人工核对] $100.5M、6 轮、2012-11 E 轮 $35M 一致；数据是母公司 HubSpot 的
A22: 21 | B22: Q05 | C22: Find competitors of Calendly | D22: Cal.com | E22: [funding] $7.4m seed round led by Joseph Jacks of OSS Capital (2022); later $25.0M Series A in April 2022; total raised about $32.4M over 2 rounds. | F22: https://cal.com/blog/seed | G22: https://startupintros.com/orgs/cal-com | H22: 搜索收录 search / 搜索收录 search | I22: 通过 verified | J22: N | K22: N | L22: N | M22: N | N22: =IF(COUNTA(J22:M22)<4,"",IF(COUNTIF(J22:M22,"Y")=4,"正确","错误")) -> 错误 | O22: [人工核对] cal.com 博客是官网却标成搜索收录；种子轮 $7.4M、OSS Capital 领投对得上；startupintros 两次打不开，A 轮 $25M 与总额 $32.4M 无法核实；博客日期 2022-09 晚于所谓「之后」的 2022-04 A 轮，时间顺序有疑
A23: 22 | B23: Q05 | C23: Find competitors of Calendly | D23: Cal.com | E23: [overview] Fully customizable scheduling software for individuals, businesses taking calls, and developers building scheduling platforms where users meet users. | F23: https://cal.com | G23: https://cal.com/about | H23: 官网 official / 官网 official | I23: 通过 verified | J23: Y | K23: Y | L23: Y | M23: Y | N23: =IF(COUNTA(J23:M23)<4,"",IF(COUNTIF(J23:M23,"Y")=4,"正确","错误")) -> 正确 | O23: [人工核对] 首页原文一致
A24: 23 | B24: Q06 | C24: 查飞书、钉钉、企业微信的定价和功能 | D24: 飞书 | E24: [pricing] Lark 提供从免费入门版到 Pro 及企业版的多档套餐，具体价格需联系销售 免费策略: 提供免费入门套餐（free starter pack），具体额度未说明 | F24: https://www.larksuite.com/en_sg/plans | H24: 官网 official | I24: 重查后通过 re-queried | J24: Y | K24: Y | L24: Y | M24: N | N24: =IF(COUNTA(J24:M24)<4,"",IF(COUNTIF(J24:M24,"Y")=4,"正确","错误")) -> 错误 | O24: [人工核对] 页面公开标价 Basic $6、Pro $12（年付），并非「需联系销售」；另外 larksuite.com 是 Lark 国际版，不等于飞书
A25: 24 | B25: Q06 | C25: 查飞书、钉钉、企业微信的定价和功能 | D25: 钉钉 | E25: [features] 企业级智能移动办公平台，提供组织协同办公、应用开发、AI 工作现场与 DingTalk A1 硬件 | F25: https://www.dingtalk.com/ | H25: 官网 official | I25: 重查后通过 re-queried | J25: Y | K25: Y | L25: Y | M25: Y | N25: =IF(COUNTA(J25:M25)<4,"",IF(COUNTIF(J25:M25,"Y")=4,"正确","错误")) -> 正确 | O25: [人工核对] AI 办公平台、宜搭应用开发、DingTalk A1 均在官网
A26: 25 | B26: Q07 | C26: Zoom, Microsoft Teams, Google Meet: pricing and recent news | D26: Zoom | E26: [pricing] Basic free / Pro $16.99 per user/month billed monthly ($14.16 annually) / Business $21.99 monthly ($18.33 annually) / Enterprise contact sales Pricing unit: Per user per month, in USD Billing: Monthly or annual billing; annual rates are lower (Pro $14.16 vs $16.99, Business $18.33 vs $21.99), in USD Free tier & trial: Basic plan free: 40-minute meetings, 100 participants, 3 meeting summaries and 20 AI queries per month | F26: https://zoom.us/pricing | H26: 官网 official | I26: 通过 verified | J26: Y | K26: Y | L26: Y | M26: Y | N26: =IF(COUNTA(J26:M26)<4,"",IF(COUNTIF(J26:M26,"Y")=4,"正确","错误")) -> 正确 | O26: [人工核对] 默认显示新币，切换为美元后 Pro $14.16、Business $18.33（年付）与免费版 40 分钟/100 人一致
A27: 26 | B27: Q07 | C27: Zoom, Microsoft Teams, Google Meet: pricing and recent news | D27: Google Meet | E27: [pricing] Starter $9.40 / Standard $18.80 / Plus $29.40 per user/month; Enterprise "Let's talk" (Contact sales) Pricing unit: Per user per month, tax excluded; Starter/Standard/Plus max 300 users, no minimum stated Billing: Annual with 1-year commitment saves 16%; all plans billed monthly, prices in SGD Extra costs: Assured Controls & AI Classification available as add-on for Enterprise Free tier & trial: 14-day free trial; no free Workspace plan listed Current offer: Up to 30% off first 3 months (Nov 8, 2026–Feb 8, 2027); intro price for first 20 users, 12 months | F27: https://workspace.google.com/pricing | H27: 官网 official | I27: 通过 verified | J27: Y | K27: Y | L27: Y | M27: N | N27: =IF(COUNTA(J27:M27)<4,"",IF(COUNTIF(J27:M27,"Y")=4,"正确","错误")) -> 错误 | O27: [人工核对] 主价 $9.40/$18.80/$29.40（SGD）、14 天试用一致；页面优惠现为前 3 个月 50% off（2026-11-09 至 2027-02-09），不是 30%（可能是优惠已更新）
A28: 27 | B28: Q07 | C28: Zoom, Microsoft Teams, Google Meet: pricing and recent news | D28: Zoom | E28: [news] 5 recent updates news.google.com: A nonprofit founder uses Zoom AI to turn meetings into finished follow-up work. news.google.com: Zoom explained how its Unified Context Layer keeps meeting context available for IT teams. news.google.com: Zoom launched a Unified Context Layer to turn meeting conversations into completed work. news.google.com: Zoom announced new Zoom Meetings features that turn conversations into completed work. news.google.com: Zoom added World's 'Proof of Human' badges to fight fraud and deep fakes. | F28: https://news.google.com/rss/articles/CBMia0FVX3lxTE52czFOS0owbEhHa21mc05wck9BSDVzT1JOalViZnRFcTJKY0lHNkgyX3liQk5SZVJuNV9sN2IzZmZjb1NaVUpYdVFmMUp0Z3o4TUR0Z2pDTFBqUTk3ZS1SRURIdV9XSkVmNFg0?oc=5 | G28: https://news.google.com/rss/articles/CBMiakFVX3lxTFBmcUFFVGltR29GUU1qSzgta0k0MV95VGV2RmdwQ2ZZUGhSelVBTHBESklzM1ZKTEFPX21GUC1ob0MzVnBBenRSWTVBSzdQelVpankycklNRE1ER25ka1NnZE1nbnVTUl9UY0E?oc=5 | H28: 新闻 news / 新闻 news | I28: 通过 verified | J28: Y | K28: Y | L28: Y | M28: Y | N28: =IF(COUNTA(J28:M28)<4,"",IF(COUNTIF(J28:M28,"Y")=4,"正确","错误")) -> 正确 | O28: [人工核对] 两条链接跳转到 Zoom 官方博客对应文章
A29: 28 | B29: Q07 | C29: Zoom, Microsoft Teams, Google Meet: pricing and recent news | D29: Microsoft Teams | E29: [news] 5 recent updates news.google.com: Workers shared tips on appearing active in Microsoft Teams, while Newsweek examined whether employers can detect such ta news.google.com: Windows Central reported that Microsoft Teams added a long-requested feature, which the writer said could bring them bac news.google.com: Purdue University Northwest announced its migration to Microsoft Teams Calling. news.google.com: Google Meet and Microsoft Teams improved their interoperability, according to Android Authority. news.google.com: Microsoft said it will remove the Copilot shortcut from the Teams chat list next month. | F29: https://news.google.com/rss/articles/CBMiqwFBVV95cUxQNW1ldWxsaC1Lb2NPYkUyWndzSXpiZlNvZUpGVUZyQTdkcFVMbTl6dXFjRWZHRURzbjBFY2wtVVA3NEVLUWZmZmdlMkdxZm5mWlMyVFVBSmRKUmVOUVh3VERKLWVfQmlzX1FvWm1yanhabWN3SDJhbFF5cGhkb3kxMGxLeXBtVVRpNEVMckdTUGxEVTNzMFRUYmE0ZVRfeXJPb3c1aDlxNFJPSjQ?oc=5 | G29: https://news.google.com/rss/articles/CBMiyAFBVV95cUxQZ0UtTGdQYVp2VllBaS1qQU9abXpxUFhJUmk5UEt5Q3NfeUcxRDZPSTl4c3JGSzhxV19Nc3luejNxM2luUXhEaUtQbkpVWnVERGFJaHQ5TDJrZmtOb1B1RWZPQjUxeHlZYThURWdFSHBUOGFueHRmSmI0REptamdsYXNuZ3JHS3VWSURUWktHT0I1TGw2Wl96OFVqdU02cGJEcFNLTE91dEp4YXUwSHdlWUdJb2NqTElyOFJGUW5aMEtDUGJHRFVTZQ?oc=5 | H29: 新闻 news / 新闻 news | I29: 通过 verified | J29: Y | K29: Y | L29: Y | M29: Y | N29: =IF(COUNTA(J29:M29)<4,"",IF(COUNTIF(J29:M29,"Y")=4,"正确","错误")) -> 正确 | O29: [人工核对] 链接跳转 Newsweek 对应文章
A30: 29 | B30: Q07 | C30: Zoom, Microsoft Teams, Google Meet: pricing and recent news | D30: Google Meet | E30: [news] 5 recent updates news.google.com: Google Meet now supports 1080p video resolution, with a caveat noted by Mashable. news.google.com: TechRadar lists 12 alternatives to Google Meet for better privacy and more powerful features. news.google.com: Hackers are using fake Google Meet pages to steal Google credentials, CyberSecurityNews reports. news.google.com: Google Meet added automated tasks and stronger security features, SammyGuru reports. news.google.com: Google Meet and Microsoft Teams improved their interoperability for working together. | F30: https://news.google.com/rss/articles/CBMiYkFVX3lxTE56VGoxN1dUZkpZWEtTeGhQRzd6WlFqS2pwVTFDVHpkSW5aX2hVVktMVWhaNjlmU0xoUVU0d0ZWM2dyeGVFOVZJeUNRZFFUQURlazBOT1ZFMldTNG52ZjNCd19B?oc=5 | G30: https://news.google.com/rss/articles/CBMiwgFBVV95cUxPTGxuMVdQOUlvclJfTzU2dE14Qm51S1NMZWZXOXhHeGdxck8zSEtxaDFLYzlOajJ5ZDRWQ3RsVzNEaGxhQUtuZmlpZmxhVFp6SkNiendPWm1XeGM1cHIxZXV2Y0FBeFVEU3BPNTYwN3pXQkp2QlE4akRWR21FOUJhVS1wUDNURmNCU2I0dVBPNXVhMnJneGZWTGJmSzlPOU55NkgxazVoY2JmeXdrLTJOV0RkOGtTdDdoVnJra0ZsNXRCQQ?oc=5 | H30: 新闻 news / 新闻 news | I30: 通过 verified | J30: Y | K30: Y | L30: Y | M30: Y | N30: =IF(COUNTA(J30:M30)<4,"",IF(COUNTIF(J30:M30,"Y")=4,"正确","错误")) -> 正确 | O30: [人工核对] 链接跳转 Mashable 1080p 文章；该文较旧，「近期」存疑
A31: 30 | B31: Q08 | C31: 我们做 SaaS 客服系统，帮我找竞品 | D31: Help Scout | E31: [size] 约140人，分布于全球115多个城市（官网招聘页，未注明年份） | F31: https://www.helpscout.com/company/careers/ | H31: 官网 official | I31: 通过 verified | J31: Y | K31: Y | L31: Y | M31: Y | N31: =IF(COUNTA(J31:M31)<4,"",IF(COUNTIF(J31:M31,"Y")=4,"正确","错误")) -> 正确 | O31: [人工核对] 140 名成员、115+ 城市一致
A32: 31 | B32: Q08 | C32: 我们做 SaaS 客服系统，帮我找竞品 | D32: Help Scout | E32: [overview] 面向成长型企业的客户沟通与客服平台，提供共享收件箱、AI客服Envoy、Copilot和Signal，服务1.2万多家客户团队 | F32: https://www.helpscout.com/about/ | G32: https://www.helpscout.com | H32: 官网 official / 官网 official | I32: 通过 verified | J32: Y | K32: Y | L32: Y | M32: Y | N32: =IF(COUNTA(J32:M32)<4,"",IF(COUNTIF(J32:M32,"Y")=4,"正确","错误")) -> 正确 | O32: [人工核对] 12,000+ 团队、收件箱/Copilot/Signal 一致；AI 客服在导航里叫 Agent，未见 Envoy 字样
A33: 32 | B33: Q08 | C33: 我们做 SaaS 客服系统，帮我找竞品 | D33: Freshdesk | E33: [overview] Freshworks 旗下 AI 客户服务软件，提供全渠道工单、自动化工作流与 Freddy AI，面向客服团队 | F33: https://www.freshworks.com/freshdesk/ | G33: https://www.freshworks.com/company/about/ | H33: 官网 official / 官网 official | I33: 通过 verified | J33: Y | K33: Y | L33: Y | M33: Y | N33: =IF(COUNTA(J33:M33)<4,"",IF(COUNTIF(J33:M33,"Y")=4,"正确","错误")) -> 正确 | O33: [人工核对] AI 客服、工作流、Freddy AI 均有
A34: 33 | B34: Q08 | C34: 我们做 SaaS 客服系统，帮我找竞品 | D34: Zendesk | E34: [overview] 服务优先的CRM公司，提供AI客服与员工服务软件，覆盖工单、消息、语音和知识库，服务8万多家企业 | F34: https://www.zendesk.com/sg/company/ | G34: https://www.zendesk.com/sg/company/agreements-and-terms/privacy-notice/ | H34: 官网 official / 官网 official | I34: 通过 verified | J34: Y | K34: Y | L34: Y | M34: Y | N34: =IF(COUNTA(J34:M34)<4,"",IF(COUNTIF(J34:M34,"Y")=4,"正确","错误")) -> 正确 | O34: [人工核对] 80,000+ 公司、员工服务一致
A35: 34 | B35: Q08 | C35: 我们做 SaaS 客服系统，帮我找竞品 | D35: Help Scout | E35: [region] 美国 · 特拉华州公益公司（PBC），团队远程分布于全球115多个城市 | F35: https://www.helpscout.com/company/legal/terms-of-service/ | G35: https://www.helpscout.com/about/ | H35: 官网 official / 官网 official | I35: 通过 verified | J35: Y | K35: Y | L35: Y | M35: Y | N35: =IF(COUNTA(J35:M35)<4,"",IF(COUNTIF(J35:M35,"Y")=4,"正确","错误")) -> 正确 | O35: [人工核对] 服务条款写明特拉华州公益公司 Help Scout PBC；about 页写远程 115+ 城市
A36: 35 | B36: Q09 | C36: Figma vs Canva vs Sketch | D36: Figma | E36: [pricing] Starter Free / Professional Full seat $16 /mo, Dev seat $12 /mo, Collab seat $3 /mo / Organization Full seat $55 /mo, Dev seat $25 /mo, Collab seat $5 /mo / Enterprise Full seat $90 /mo, Dev seat $35 /mo, Collab seat $5 /mo Pricing unit: Per seat per month, with three seat types: Full seat, Dev seat and Collab seat. Billing: Prices in USD; Professional offers Monthly or Annual, Organization and Enterprise are billed annually. Free tier & trial: Starter is free with limited access: unlimited drafts, UI kits and templates, 150 AI credits/day up to 500 AI credits/mo. Current offer: AI add-ons are now available for all plans. | F36: https://www.figma.com/pricing/ | H36: 官网 official | I36: 通过 verified | J36: Y | K36: Y | L36: Y | M36: Y | N36: =IF(COUNTA(J36:M36)<4,"",IF(COUNTIF(J36:M36,"Y")=4,"正确","错误")) -> 正确 | O36: [人工核对] 三档席位价与 Starter 150/天、500/月 AI 额度一致
A37: 36 | B37: Q09 | C37: Figma vs Canva vs Sketch | D37: Canva | E37: [pricing] Free US$0 / Pro US$144/year for one person / Business US$250/year per person / Enterprise contact sales Pricing unit: Per person (per seat) per year; Business priced per person Billing: Yearly billing shown with monthly toggle; yearly saves from 16% Extra costs: AI Pass add-on and AI top-ups available at extra cost on Pro and Business Free tier & trial: Free plan: 5GB storage, 1 Brand Kit (3 colors), up to 20 Standard or Premium AI uses Current offer: Yearly billing saves from 16% versus monthly | F37: https://www.canva.com/pricing/ | G37: https://www.canva.com/help/subscription-options/ | H37: 官网 official / 搜索收录 search | I37: 通过 verified | J37: Y | K37: Y | L37: N | M37: Y | N37: =IF(COUNTA(J37:M37)<4,"",IF(COUNTIF(J37:M37,"Y")=4,"正确","错误")) -> 错误 | O37: [人工核对] 切到美国地区后 Pro US$144、Business US$250、年付省 16%、免费 5GB 一致；但来源 2 是 Canva 官方帮助中心，却标成搜索收录
A38: 37 | B38: Q09 | C38: Figma vs Canva vs Sketch | D38: Sketch | E38: [pricing] Standard subscription (monthly per Editor, billed yearly) and Mac-only license (per Seat, $120 yearly seat cost); no full plan list with prices shown. Pricing unit: Per Editor per month, billed yearly; Mac-only license is per seat including one year of updates Billing: Prices shown are monthly per Editor billed yearly; a Monthly toggle exists; Professional plans billed yearly by credit card Extra costs: One-time setup fee for Private Cloud plans; additional charges may apply for custom requirements Free tier & trial: No free plan; 30-day free trial without credit card; unlimited free Viewers; free Education Workspace with 1 Editor seat Current offer: Free for education: students and educators get one year of free access | F38: https://www.sketch.com/license/ | G38: https://www.sketch.com/pricing/ | H38: 官网 official / 官网 official | I38: 重查后通过 re-queried | J38: Y | K38: Y | L38: Y | M38: N | N38: =IF(COUNTA(J38:M38)<4,"",IF(COUNTIF(J38:M38,"Y")=4,"正确","错误")) -> 错误 | O38: [人工核对] 页面明码标价 Standard $12 / Professional $24 / Enterprise $44（年付），系统却写「未列出完整价格」
A39: 38 | B39: Q09 | C39: Figma vs Canva vs Sketch | D39: Sketch | E39: [overview] Sketch is a macOS design toolkit made by designers for designers, covering design, prototyping, collaboration and developer handoff for UI/UX designers. | F39: https://www.sketch.com | G39: https://www.sketch.com/about-us/ | H39: 官网 official / 官网 official | I39: 通过 verified | J39: Y | K39: Y | L39: Y | M39: Y | N39: =IF(COUNTA(J39:M39)<4,"",IF(COUNTIF(J39:M39,"Y")=4,"正确","错误")) -> 正确 | O39: [人工核对] about 页写专注为 UI/UX 设计师做 Mac 应用；设计/原型/协作/交付在导航中
A40: 39 | B40: Q09 | C40: Figma vs Canva vs Sketch | D40: Canva | E40: [news] 5 recent updates news.google.com: Canva unveiled its first AI image model, which plans designs before generating them. news.google.com: Canva released its first image generation model, according to TechCrunch. news.google.com: Canva scaled up threat detection using data it already trusts, per Snowflake. news.google.com: An activist disrupted Canva's AI event in London, saying 'AI steals from people.' news.google.com: The American Film Institute named its 2026-2027 Canva Fellowship recipients. | F40: https://news.google.com/rss/articles/CBMikwFBVV95cUxQR05XNUt3S2l1QkotOUJTMG1HZlpaeWFTXzFFbXZHOFpIa25pODdkTXdvd2VTS2tZb1pKY05ieHB6YUtPLW5DNUpPTzlPc3BDd0dFY3VDSVc3U05VcEV2LVAxVjNfaF9aZGk3bEVCVTlxQ0ZFUExzMWxjUHFTcVpPa1BseW5rdFl1dmN6REd2TkxVWjA?oc=5 | G40: https://news.google.com/rss/articles/CBMiigFBVV95cUxNd21jWkQ5TzJTSGZRdl9YQVBqMWNLR3JRME9XX0JiZUJ4OXRFbjZSeWZ3NTlrT3VPLWhQeElXbzJueHAzU1hhUlB6LXFWQ1MyQXFPcUJ1ZU9Vd0ZjbkFmWjY4Y05JOU9KNGk4d3FIVTA5aFhUeHJueG5RVnhwNjgwcUpMQzBiUUc2OEE?oc=5 | H40: 新闻 news / 新闻 news | I40: 通过 verified | J40: Y | K40: Y | L40: Y | M40: Y | N40: =IF(COUNTA(J40:M40)<4,"",IF(COUNTIF(J40:M40,"Y")=4,"正确","错误")) -> 正确 | O40: [人工核对] 链接跳转 The Verge 对应文章
...

Sheet 汇总 Summary
A1: 项目 Item | B1: 值 Value
A2: 已核对条数 Audited | B2: =COUNTIF('核对 Audit'!N2:N51,"正确")+COUNTIF('核对 Audit'!N2:N51,"错误") -> 48
A3: 正确 Correct | B3: =COUNTIF('核对 Audit'!N2:N51,"正确") -> 33
A4: 错误 Wrong | B4: =COUNTIF('核对 Audit'!N2:N51,"错误") -> 15
A5: 正确率 Correct rate | B5: =IF(B2=0,"",B3/B2) -> 0.6875
A6: 门槛 Threshold (measure 1) | B6: 0.9
A7: 结论 Verdict | B7: =IF(B2<50,"未完成 incomplete",IF(B5>=0.9,"达成 MET",IF(B5<0.8,"证伪 FALSIFIED (F1)","未达成 MISSED"))) -> 未完成 incomplete
A9: 其中：官网来源正确率 official-source rows | B9: =IFERROR(COUNTIFS('核对 Audit'!H2:H51,"官网*",'核对 Audit'!N2:N51,"正确")/(COUNTIFS('核对 Audit'!H2:H51,"官网*",'核对 Audit'!N2:N51,"正确")+COUNTIFS('核对 Audit'!H2:H51,"官网*",'核对 Audit'!N2:N51,"错误")),"") -> 0.72222222
A10: 各项未通过 J 链接 | B10: =COUNTIF('核对 Audit'!J2:J51,"N") -> 3
A11: 各项未通过 K 原文 | B11: =COUNTIF('核对 Audit'!K2:K51,"N") -> 3
A12: 各项未通过 L 来源/标注 | B12: =COUNTIF('核对 Audit'!L2:L51,"N") -> 9
A13: 各项未通过 M 数值 | B13: =COUNTIF('核对 Audit'!M2:M51,"N") -> 9
A15: 开始时间 Start (例 2026-10-27 10:00) | B15: 46321.867
A16: 结束时间 End | B16: 46321.912
A17: 核对用时（分钟）Audit minutes | B17: =IF(OR(B15="",B16=""),"",ROUND((B16-B15)*1440,0)) -> 64
A19: 核对者 Reviewer
A20: 待补 Pending | B20: #3、#5：开发屋 Cloudflare 真人验证需本人通过后补核
